21:06:29 [INFO] Fetching https://example.com
21:06:29 [INFO] Fetching https://news.ycombinator.com
21:06:30 [INFO] Fetched https://example.com (Status 200)
21:06:30 [INFO] Fetched https://example.com in 0.67s
21:06:30 [ERROR] Failed to save https://example.com: 
**********************************************************************
  Resource [93mpunkt_tab[0m not found.
  Please use the NLTK Downloader to obtain the resource:

  [31m>>> import nltk
  >>> nltk.download('punkt_tab')
  [0m
  For more information see: https://www.nltk.org/data.html

  Attempted to load [93mtokenizers/punkt_tab/english/[0m

  Searched in:
    - '/home/toast/nltk_data'
    - '/home/toast/miniconda3/envs/inf_retr/nltk_data'
    - '/home/toast/miniconda3/envs/inf_retr/share/nltk_data'
    - '/home/toast/miniconda3/envs/inf_retr/lib/nltk_data'
    - '/usr/share/nltk_data'
    - '/usr/local/share/nltk_data'
    - '/usr/lib/nltk_data'
    - '/usr/local/lib/nltk_data'
**********************************************************************

21:06:32 [INFO] Fetched https://news.ycombinator.com (Status 200)
21:06:32 [INFO] Fetched https://news.ycombinator.com in 2.44s
21:06:32 [ERROR] Failed to save https://news.ycombinator.com: 
**********************************************************************
  Resource [93mpunkt_tab[0m not found.
  Please use the NLTK Downloader to obtain the resource:

  [31m>>> import nltk
  >>> nltk.download('punkt_tab')
  [0m
  For more information see: https://www.nltk.org/data.html

  Attempted to load [93mtokenizers/punkt_tab/english/[0m

  Searched in:
    - '/home/toast/nltk_data'
    - '/home/toast/miniconda3/envs/inf_retr/nltk_data'
    - '/home/toast/miniconda3/envs/inf_retr/share/nltk_data'
    - '/home/toast/miniconda3/envs/inf_retr/lib/nltk_data'
    - '/usr/share/nltk_data'
    - '/usr/local/share/nltk_data'
    - '/usr/lib/nltk_data'
    - '/usr/local/lib/nltk_data'
**********************************************************************

21:06:32 [INFO] Crawling finished.
21:06:32 [INFO] Total seen URLs: 2
21:06:32 [INFO] Total successfully visited URLs: 0
21:13:28 [INFO] Fetching https://example.com
21:13:28 [INFO] Fetching https://news.ycombinator.com
21:13:29 [INFO] Fetched https://example.com (Status 200)
21:13:29 [INFO] Fetched https://example.com in 0.78s
21:13:29 [ERROR] Failed to save https://example.com: 
**********************************************************************
  Resource [93maveraged_perceptron_tagger_eng[0m not found.
  Please use the NLTK Downloader to obtain the resource:

  [31m>>> import nltk
  >>> nltk.download('averaged_perceptron_tagger_eng')
  [0m
  For more information see: https://www.nltk.org/data.html

  Attempted to load [93mtaggers/averaged_perceptron_tagger_eng/[0m

  Searched in:
    - '/home/toast/nltk_data'
    - '/home/toast/miniconda3/envs/inf_retr/nltk_data'
    - '/home/toast/miniconda3/envs/inf_retr/share/nltk_data'
    - '/home/toast/miniconda3/envs/inf_retr/lib/nltk_data'
    - '/usr/share/nltk_data'
    - '/usr/local/share/nltk_data'
    - '/usr/lib/nltk_data'
    - '/usr/local/lib/nltk_data'
**********************************************************************

21:13:31 [INFO] Fetched https://news.ycombinator.com (Status 200)
21:13:31 [INFO] Fetched https://news.ycombinator.com in 2.73s
21:13:31 [ERROR] Failed to save https://news.ycombinator.com: 
**********************************************************************
  Resource [93maveraged_perceptron_tagger_eng[0m not found.
  Please use the NLTK Downloader to obtain the resource:

  [31m>>> import nltk
  >>> nltk.download('averaged_perceptron_tagger_eng')
  [0m
  For more information see: https://www.nltk.org/data.html

  Attempted to load [93mtaggers/averaged_perceptron_tagger_eng/[0m

  Searched in:
    - '/home/toast/nltk_data'
    - '/home/toast/miniconda3/envs/inf_retr/nltk_data'
    - '/home/toast/miniconda3/envs/inf_retr/share/nltk_data'
    - '/home/toast/miniconda3/envs/inf_retr/lib/nltk_data'
    - '/usr/share/nltk_data'
    - '/usr/local/share/nltk_data'
    - '/usr/lib/nltk_data'
    - '/usr/local/lib/nltk_data'
**********************************************************************

21:13:31 [INFO] Crawling finished.
21:13:31 [INFO] Total seen URLs: 2
21:13:31 [INFO] Total successfully visited URLs: 0
21:23:39 [INFO] Fetching https://example.com
21:23:39 [WARNING] Could not read robots.txt for ://: unknown url type: ':///robots.txt'
21:23:39 [ERROR] Client error while fetching URIReference(scheme='https', authority='example.com', path=None, query=None, fragment=None): URIReference(scheme='https',%20authority='example.com',%20path=None,%20query=None,%20fragment=None)
21:23:39 [INFO] Fetching https://news.ycombinator.com
21:23:41 [ERROR] Client error while fetching URIReference(scheme='https', authority='news.ycombinator.com', path=None, query=None, fragment=None): URIReference(scheme='https',%20authority='news.ycombinator.com',%20path=None,%20query=None,%20fragment=None)
21:24:02 [ERROR] Task exception was never retrieved
future: <Task finished name='Task-3' coro=<Scheduler.spider() done, defined at /home/toast/Documents/data_science/infoRetr/Exam_IR/scheduler.py:160> exception=NameError("name 'aiohttp' is not defined")>
Traceback (most recent call last):
  File "/home/toast/Documents/data_science/infoRetr/Exam_IR/scheduler.py", line 108, in fetch_url
  File "/home/toast/Documents/data_science/infoRetr/Exam_IR/fetcher.py", line 130, in fetch
  File "/home/toast/miniconda3/envs/inf_retr/lib/python3.13/site-packages/aiohttp/client.py", line 1482, in __aenter__
  File "/home/toast/miniconda3/envs/inf_retr/lib/python3.13/site-packages/aiohttp/client.py", line 637, in _request
aiohttp.client_exceptions.InvalidUrlClientError: URIReference(scheme='https',%20authority='news.ycombinator.com',%20path=None,%20query=None,%20fragment=None)

During handling of the above exception, another exception occurred:

Traceback (most recent call last):
  File "/home/toast/Documents/data_science/infoRetr/Exam_IR/scheduler.py", line 166, in spider
  File "/home/toast/Documents/data_science/infoRetr/Exam_IR/scheduler.py", line 112, in fetch_url
NameError: name 'aiohttp' is not defined
21:24:02 [ERROR] Task exception was never retrieved
future: <Task finished name='Task-2' coro=<Scheduler.spider() done, defined at /home/toast/Documents/data_science/infoRetr/Exam_IR/scheduler.py:160> exception=NameError("name 'aiohttp' is not defined")>
Traceback (most recent call last):
  File "/home/toast/Documents/data_science/infoRetr/Exam_IR/scheduler.py", line 108, in fetch_url
  File "/home/toast/Documents/data_science/infoRetr/Exam_IR/fetcher.py", line 130, in fetch
  File "/home/toast/miniconda3/envs/inf_retr/lib/python3.13/site-packages/aiohttp/client.py", line 1482, in __aenter__
  File "/home/toast/miniconda3/envs/inf_retr/lib/python3.13/site-packages/aiohttp/client.py", line 637, in _request
aiohttp.client_exceptions.InvalidUrlClientError: URIReference(scheme='https',%20authority='example.com',%20path=None,%20query=None,%20fragment=None)

During handling of the above exception, another exception occurred:

Traceback (most recent call last):
  File "/home/toast/Documents/data_science/infoRetr/Exam_IR/scheduler.py", line 166, in spider
  File "/home/toast/Documents/data_science/infoRetr/Exam_IR/scheduler.py", line 112, in fetch_url
NameError: name 'aiohttp' is not defined
21:41:33 [INFO] Fetching https://example.com
21:41:33 [WARNING] Could not read robots.txt for ://: unknown url type: ':///robots.txt'
21:41:33 [ERROR] Client error while fetching URIReference(scheme='https', authority='example.com', path=None, query=None, fragment=None): URIReference(scheme='https',%20authority='example.com',%20path=None,%20query=None,%20fragment=None)
21:41:33 [INFO] Fetching https://news.ycombinator.com
21:41:34 [ERROR] Client error while fetching URIReference(scheme='https', authority='news.ycombinator.com', path=None, query=None, fragment=None): URIReference(scheme='https',%20authority='news.ycombinator.com',%20path=None,%20query=None,%20fragment=None)
21:42:14 [ERROR] Task exception was never retrieved
future: <Task finished name='Task-3' coro=<Scheduler.spider() done, defined at /home/toast/Documents/data_science/infoRetr/Exam_IR/scheduler.py:158> exception=NameError("name 'aiohttp' is not defined")>
Traceback (most recent call last):
  File "/home/toast/Documents/data_science/infoRetr/Exam_IR/scheduler.py", line 106, in fetch_url
  File "/home/toast/Documents/data_science/infoRetr/Exam_IR/fetcher.py", line 130, in fetch
  File "/home/toast/miniconda3/envs/inf_retr/lib/python3.13/site-packages/aiohttp/client.py", line 1482, in __aenter__
  File "/home/toast/miniconda3/envs/inf_retr/lib/python3.13/site-packages/aiohttp/client.py", line 637, in _request
aiohttp.client_exceptions.InvalidUrlClientError: URIReference(scheme='https',%20authority='news.ycombinator.com',%20path=None,%20query=None,%20fragment=None)

During handling of the above exception, another exception occurred:

Traceback (most recent call last):
  File "/home/toast/Documents/data_science/infoRetr/Exam_IR/scheduler.py", line 164, in spider
  File "/home/toast/Documents/data_science/infoRetr/Exam_IR/scheduler.py", line 110, in fetch_url
NameError: name 'aiohttp' is not defined
21:42:14 [ERROR] Task exception was never retrieved
future: <Task finished name='Task-2' coro=<Scheduler.spider() done, defined at /home/toast/Documents/data_science/infoRetr/Exam_IR/scheduler.py:158> exception=NameError("name 'aiohttp' is not defined")>
Traceback (most recent call last):
  File "/home/toast/Documents/data_science/infoRetr/Exam_IR/scheduler.py", line 106, in fetch_url
  File "/home/toast/Documents/data_science/infoRetr/Exam_IR/fetcher.py", line 130, in fetch
  File "/home/toast/miniconda3/envs/inf_retr/lib/python3.13/site-packages/aiohttp/client.py", line 1482, in __aenter__
  File "/home/toast/miniconda3/envs/inf_retr/lib/python3.13/site-packages/aiohttp/client.py", line 637, in _request
aiohttp.client_exceptions.InvalidUrlClientError: URIReference(scheme='https',%20authority='example.com',%20path=None,%20query=None,%20fragment=None)

During handling of the above exception, another exception occurred:

Traceback (most recent call last):
  File "/home/toast/Documents/data_science/infoRetr/Exam_IR/scheduler.py", line 164, in spider
  File "/home/toast/Documents/data_science/infoRetr/Exam_IR/scheduler.py", line 110, in fetch_url
NameError: name 'aiohttp' is not defined
21:43:32 [INFO] Fetching https://example.com
21:43:32 [WARNING] Could not read robots.txt for ://: unknown url type: ':///robots.txt'
21:43:32 [ERROR] Client error while fetching URIReference(scheme='https', authority='example.com', path=None, query=None, fragment=None): URIReference(scheme='https',%20authority='example.com',%20path=None,%20query=None,%20fragment=None)
21:43:32 [ERROR] Fetch failed for https://example.com after 0.00s: URIReference(scheme='https',%20authority='example.com',%20path=None,%20query=None,%20fragment=None)
21:43:32 [ERROR] Fetch failed for https://example.com: URIReference(scheme='https',%20authority='example.com',%20path=None,%20query=None,%20fragment=None)
21:43:32 [INFO] Re-queuing https://example.com (attempt 1)
21:43:32 [WARNING] Empty response for https://example.com
21:43:32 [INFO] Fetching https://news.ycombinator.com
21:43:32 [INFO] Fetching https://example.com
21:43:34 [ERROR] Client error while fetching URIReference(scheme='https', authority='example.com', path=None, query=None, fragment=None): URIReference(scheme='https',%20authority='example.com',%20path=None,%20query=None,%20fragment=None)
21:43:34 [ERROR] Fetch failed for https://example.com after 1.50s: URIReference(scheme='https',%20authority='example.com',%20path=None,%20query=None,%20fragment=None)
21:43:34 [ERROR] Fetch failed for https://example.com: URIReference(scheme='https',%20authority='example.com',%20path=None,%20query=None,%20fragment=None)
21:43:34 [INFO] Re-queuing https://example.com (attempt 2)
21:43:34 [WARNING] Empty response for https://example.com
21:43:34 [INFO] Fetching https://example.com
21:43:34 [ERROR] Client error while fetching URIReference(scheme='https', authority='news.ycombinator.com', path=None, query=None, fragment=None): URIReference(scheme='https',%20authority='news.ycombinator.com',%20path=None,%20query=None,%20fragment=None)
21:43:34 [ERROR] Fetch failed for https://news.ycombinator.com after 1.50s: URIReference(scheme='https',%20authority='news.ycombinator.com',%20path=None,%20query=None,%20fragment=None)
21:43:34 [ERROR] Fetch failed for https://news.ycombinator.com: URIReference(scheme='https',%20authority='news.ycombinator.com',%20path=None,%20query=None,%20fragment=None)
21:43:34 [INFO] Re-queuing https://news.ycombinator.com (attempt 1)
21:43:34 [WARNING] Empty response for https://news.ycombinator.com
21:43:34 [INFO] Fetching https://news.ycombinator.com
21:43:35 [ERROR] Client error while fetching URIReference(scheme='https', authority='example.com', path=None, query=None, fragment=None): URIReference(scheme='https',%20authority='example.com',%20path=None,%20query=None,%20fragment=None)
21:43:35 [ERROR] Fetch failed for https://example.com after 1.50s: URIReference(scheme='https',%20authority='example.com',%20path=None,%20query=None,%20fragment=None)
21:43:35 [ERROR] Fetch failed for https://example.com: URIReference(scheme='https',%20authority='example.com',%20path=None,%20query=None,%20fragment=None)
21:43:35 [INFO] Giving up on https://example.com after 3 attempts.
21:43:35 [WARNING] Empty response for https://example.com
21:43:35 [ERROR] Client error while fetching URIReference(scheme='https', authority='news.ycombinator.com', path=None, query=None, fragment=None): URIReference(scheme='https',%20authority='news.ycombinator.com',%20path=None,%20query=None,%20fragment=None)
21:43:35 [ERROR] Fetch failed for https://news.ycombinator.com after 1.50s: URIReference(scheme='https',%20authority='news.ycombinator.com',%20path=None,%20query=None,%20fragment=None)
21:43:35 [ERROR] Fetch failed for https://news.ycombinator.com: URIReference(scheme='https',%20authority='news.ycombinator.com',%20path=None,%20query=None,%20fragment=None)
21:43:35 [INFO] Re-queuing https://news.ycombinator.com (attempt 2)
21:43:35 [WARNING] Empty response for https://news.ycombinator.com
21:43:35 [INFO] Fetching https://news.ycombinator.com
21:43:37 [ERROR] Client error while fetching URIReference(scheme='https', authority='news.ycombinator.com', path=None, query=None, fragment=None): URIReference(scheme='https',%20authority='news.ycombinator.com',%20path=None,%20query=None,%20fragment=None)
21:43:37 [ERROR] Fetch failed for https://news.ycombinator.com after 1.50s: URIReference(scheme='https',%20authority='news.ycombinator.com',%20path=None,%20query=None,%20fragment=None)
21:43:37 [ERROR] Fetch failed for https://news.ycombinator.com: URIReference(scheme='https',%20authority='news.ycombinator.com',%20path=None,%20query=None,%20fragment=None)
21:43:37 [INFO] Giving up on https://news.ycombinator.com after 3 attempts.
21:43:37 [WARNING] Empty response for https://news.ycombinator.com
21:43:37 [INFO] Crawling finished.
21:43:37 [INFO] Total seen URLs: 2
21:43:37 [INFO] Total successfully visited URLs: 0
